Workbook

Sheet 요약
A1: [Global] | H1: 1450
E2: 1.2M TCV | F2: 1.5M TCV | G2: 2.25 TCV | H2: 3.375 TCV
A3: 구분 | B3: 2023년 | C3: 2024년 | D3: 2025년 | E3: 2026년 | F3: 2027년 | G3: 2028년 | H3: 2029년 | I3: 비고
A4: 기존매출 | C4: ='Global(계약시점)'!N44*H1 -> 3697500 | D4: ='Global(계약시점)'!Z44*H1 -> 1.3294953e+08 | E4: ='Global(계약시점)'!AL44*H1 -> 4.3931658e+08 | F4: ='Global(계약시점)'!AY44*H1 -> 1.0231112e+09 | G4: ='Global(계약시점)'!BK44*H1 -> 1.7379334e+09 | H4: ='Global(계약시점)'!BW44*H1 -> 1.4548309e+09 | I4: 3년계약으로 반영
A5: 신규매출 | B5: ='Global(계약시점)'!K44*H1 -> 3697500 | C5: ='Global(계약시점)'!N47*H1 -> 2.3383594e+08 | D5: ='Global(계약시점)'!Z47*H1 -> 72478661 | E5: ='Global(계약시점)'!AL47*H1 -> 251328500 | F5: ='Global(계약시점)'!AY47*H1 -> 302088650 | G5: =('Global(계약시점)'!G45+'Global(계약시점)'!G46+'Global(계약시점)'!G47+'Global(계약시점)'!G48)*H1 -> 366125000 | H5: =G5+G5*20% -> 439350000 | I5: 연 150% 성장
A6: 매출원가 | B6: =(B4+B5)*20% -> 739500 | C6: =(C4+C5)*20% -> 47506688 | D6: =(D4+D5)*20% -> 41085639 | E6: =(E4+E5)*20% -> 1.3812902e+08 | F6: =(F4+F5)*20% -> 2.6503997e+08 | G6: =(G4+G5)*20% -> 4.2081168e+08 | H6: =(H4+H5)*20% -> 3.7883619e+08 | I6: 매출의 20% | J6: 리전비용 확인 필요
A7: 판관비 | B7: 162662013 | C7: 501833535 | D7: =617645135/10*12 -> 741174162 | E7: =C65 -> 0 | F7: =E7*1.1 -> 0 | G7: =F7*1.1 -> 0 | H7: =G7*1.1+150000000 -> 150000000 | J7: 29년도 비용 1.5억 추가인데 어디에 2명을 충원할지 확인 필요
A8: 영업손익 | B8: =B4+B5-B6-B7 -> -159704013 | C8: =C4+C5-C6-C7 -> -3.1180678e+08 | D8: =D4+D5-D6-D7 -> -5.7683161e+08 | E8: =E4+E5-E6-E7 -> 552516062 | F8: =F4+F5-F6-F7 -> 1.0601599e+09 | G8: =G4+G5-G6-G7 -> 1.6832467e+09 | H8: =H4+H5-H6-H7 -> 1.3653447e+09
A9: 누적손익 | C9: =B8+C8 -> -4.7151079e+08 | D9: =C9+D8 -> -1.0483424e+09 | E9: =D9+E8 -> -4.9582634e+08 | F9: =E9+F8 -> 5.6433355e+08 | G9: =F9+G8 -> 2.2475803e+09 | H9: =G9+H8 -> 3.612925e+09 | I9: 2023년부터~
A10: 인원 | D10: 태국엔지니어 1명 | H10: 2명 충원??
D11: 인니 주니어 엔지니어 1명 | E11: 세일즈 1명
D12: 인니 Country Director 1명
D13: 인니 영업지원 1명
D14: 8 | E14: 10 | F14: 10 | G14: 10 | H14: 12
G16: =(G5-F5)/F5 -> 0.21197867
B21: 1월 | C21: 12개월 연간 반영
A22: 판관비(장부+현지 인건비) | B22: =SUM(B23:B53)-B24-B25 -> 80230089 | C22: =SUM(C23:C53)-C24-C25 -> 863849248
A23: 직 원 급 여 | B23: 30903499 | C23: =B23*12 -> 370841988
A24: - 글로벌팀(국내) | B24: 16504999
A25: - 글로벌팀(인니,태국_현지) | B25: 14398500
A26: 상 여 금 | B26: 4725443 | C26: 60000000
A27: 잡 급 | B27: 0
A28: 퇴 직 급 여 | B28: 0
A29: 복 리 후 생 비 | B29: 1467522 | C29: =B29*12 -> 17610264
A30: 복 리 _ 복 지 카 드 | B30: 1660070 | C30: =2400000*2 -> 4800000
A31: 복 리 _ 회 식 대 | B31: 121471 | C31: 3000000
A32: 복 리 _ 간 식 대 | B32: 147465 | C32: 1200000
A33: 복 리 _ 경 조 사 비 | B33: 0
A34: 복 리 _ 기 타 | B34: 42141 | C34: 1000000
A35: 여 비 교 통 비 | B35: 1383165 | C35: =B35*12 -> 16597980
A36: 여 비 _ 해 외 출 장 비 | B36: 8855664 | C36: =B36*12 -> 106267968
A37: 접 대 비(기업업무추진비) | B37: 2629276 | C37: =B37*12 -> 31551312
A38: 통 신 비 | B38: 0
A39: 세 금 과 공 과 금 | B39: 573300 | C39: =B39*12 -> 6879600
A40: 감 가 상 각 비 | B40: 0
A41: 지 급 임 차 료(앤디숙소) | B41: 824166 | C41: =B41*12 -> 9889992
A42: 보 험 료 | B42: 1420336 | C42: =B42*12 -> 17044032
A43: 차 량 유 지 비 | B43: 0
A44: 운 반 비 | B44: 0
A45: 교 육 훈 련 비 | B45: 0
...

Sheet Global(계약시점)
A1: 글로벌팀 매출액 (계약 금액, 국내 매출 기준) | E1: 환율 | F1: 1 | G1: 1400.96
K2: 2023 | N2: 2024 | Z2: 2025 | AL2: 2026 | AY2: 2027 | BK2: 2028 | BW2: 2029 | CI2: 2030
A3: 계약 년도 | B3: 관계사 | C3: 판매형태 | D3: 고객사 딜 | E3: 계약 기간 | F3: 개월수 | G3: ARR | H3: 총액 | J3: 고객사 - 제품 | K3: 10 | L3: 11 | M3: 12 | N3: 1 | O3: 2 | P3: 3 | Q3: 4 | R3: 5 | S3: 6 | T3: 7 | U3: 8 | V3: 9 | W3: 10 | X3: 11 | Y3: 12 | Z3: 1 | AA3: 2 | AB3: 3 | AC3: 4 | AD3: 5 | AE3: 6 | AF3: 7 | AG3: 8 | AH3: 9 | AI3: 10 | AJ3: 11 | AK3: 12 | AL3: 1 | AM3: 1월 원화 | AN3: 2 | AO3: 3 | AP3: 4 | AQ3: 5 | AR3: 6 | AS3: 7 | AT3: 8 | AU3: 9 | AV3: 10 | AW3: 11 | AX3: 12 | AY3: 1 | AZ3: 2 | BA3: 3 | BB3: 4 | BC3: 5 | BD3: 6 | BE3: 7 | BF3: 8 | BG3: 9 | BH3: 10 | BI3: 11 | BJ3: 12 | BK3: 1 | BL3: 2 | BM3: 3 | BN3: 4 | BO3: 5 | BP3: 6 | BQ3: 7 | BR3: 8 | BS3: 9 | BT3: 10 | BU3: 11 | BV3: 12 | BW3: 1 | BX3: 2 | BY3: 3 | BZ3: 4 | CA3: 5 | CB3: 6 | CC3: 7 | CD3: 8 | CE3: 9 | CF3: 10 | CG3: 11 | CH3: 12 | CI3: 1 | CJ3: 2 | CK3: 3 | CL3: 4 | CM3: 5 | CN3: 6 | CO3: 7 | CP3: 8 | CQ3: 9 | CR3: 10 | CS3: 11 | CT3: 12
A4: 2023 | B4: Triputra | D4: [PT. Sisnet Mitra Sejahtera][Sisnet MSP] | E4: 23.09.26 ~ 26.09.26 | F4: 6 | G4: 5100 | H4: 5100 | J4: Sisnet - MSP | K4: 850 | L4: 850 | M4: 850 | N4: 850 | O4: 850 | P4: 850 | CU4: =SUM(K4:CT4) -> 5100
A5: 2023 | B5: Triputra | D5: [FIF][FIF K8S LOG APM 23.12.31-24.12.31] | E5: 23.12.31 ~ 24.12.31 | F5: 12 | G5: 2340 | H5: 2340 | J5: FIF - K8s/Log/APM | N5: 195 | O5: 195 | P5: 195 | Q5: 195 | R5: 195 | S5: 195 | T5: 195 | U5: 195 | V5: 195 | W5: 195 | X5: 195 | Y5: 195 | CU5: =SUM(K5:CT5) -> 2340
A6: 2024 | B6: Triputra | D6: [FIF][FIF DPM LOG APM 24.04.15-26.04.14] | E6: 24.04.15~26.04.15 | F6: 24 | G6: 12457 | H6: 24914 | J6: FIF - DPM/Log/APM | Q6: 1038.0833 | R6: 1038.0833 | S6: 1038.0833 | T6: 1038.0833 | U6: 1038.0833 | V6: 1038.0833 | W6: 1038.0833 | X6: 1038.0833 | Y6: 1038.0833 | Z6: 1038.0833 | AA6: 1038.0833 | AB6: 1038.0833 | AC6: 1038.0833 | AD6: 1038.0833 | AE6: 1038.0833 | AF6: 1038.0833 | AG6: 1038.0833 | AH6: 1038.0833 | AI6: 1038.0833 | AJ6: 1038.0833 | AK6: 1038.0833 | AL6: 1038.0833 | AM6: =592703+740664+20574+19202+50749 -> 1423892 | AN6: 1038.0833 | AO6: 1038.0833 | AP6: 1038.0833 | AQ6: 1038.0833 | AR6: 1038.0833 | AS6: 1038.0833 | AT6: 1038.0833 | AU6: 1038.0833 | AV6: 1038.0833 | AW6: 1038.0833 | AX6: 1038.0833 | AY6: 1038.0833 | AZ6: 1038.0833 | BA6: 1038.0833 | BB6: 1038.0833 | BC6: 1038.0833 | BD6: 1038.0833 | BE6: 1038.0833 | BF6: 1038.0833 | BG6: 1038.0833 | BH6: 1038.0833 | BI6: 1038.0833 | BJ6: 1038.0833 | BK6: 1038.0833 | BL6: 1038.0833 | BM6: 1038.0833 | BN6: 1038.0833 | BO6: 1038.0833 | BP6: 1038.0833 | BQ6: 1038.0833 | BR6: 1038.0833 | BS6: 1038.0833 | BT6: 1038.0833 | BU6: 1038.0833 | BV6: 1038.0833 | BW6: 1038.0833 | BX6: 1038.0833 | BY6: 1038.0833 | BZ6: 1038.0833 | CA6: 1038.0833 | CB6: 1038.0833 | CC6: 1038.0833 | CD6: 1038.0833 | CE6: 1038.0833 | CF6: 1038.0833 | CG6: 1038.0833 | CH6: 1038.0833 | CI6: 1038.0833 | CJ6: 1038.0833 | CK6: 1038.0833 | CU6: =SUM(K6:CT6) -> 1498634
A7: 2024 | B7: Triputra | D7: [Adira][OnPrem Server/APM/DB_24.06-27.06] | E7: 24.06.17~27.06.17 | F7: 36 | G7: 35165 | H7: 105495 | J7: Adira - Server/APM/DB | S7: 2930.4167 | T7: 2930.4167 | U7: 2930.4167 | V7: 2930.4167 | W7: 2930.4167 | X7: 2930.4167 | Y7: 2930.4167 | Z7: 2930.4167 | AA7: 2930.4167 | AB7: 2930.4167 | AC7: 2930.4167 | AD7: 2930.4167 | AE7: 2930.4167 | AF7: 2930.4167 | AG7: 2930.4167 | AH7: 2930.4167 | AI7: 2930.4167 | AJ7: 2930.4167 | AK7: 2930.4167 | AL7: 2930.4167 | AM7: 4048078 | AN7: 2930.4167 | AO7: 2930.4167 | AP7: 2930.4167 | AQ7: 2930.4167 | AR7: 2930.4167 | AS7: 2930.4167 | AT7: 2930.4167 | AU7: 2930.4167 | AV7: 2930.4167 | AW7: 2930.4167 | AX7: 2930.4167 | AY7: 2930.4167 | AZ7: 2930.4167 | BA7: 2930.4167 | BB7: 2930.4167 | BC7: 2930.4167 | BD7: 2930.4167 | BE7: 2930.4167 | BF7: 2930.4167 | BG7: 2930.4167 | BH7: 2930.4167 | BI7: 2930.4167 | BJ7: 2930.4167 | BK7: 2930.4167 | BL7: 2930.4167 | BM7: 2930.4167 | BN7: 2930.4167 | BO7: 2930.4167 | BP7: 2930.4167 | BQ7: 2930.4167 | BR7: 2930.4167 | BS7: 2930.4167 | BT7: 2930.4167 | BU7: 2930.4167 | BV7: 2930.4167 | BW7: 2930.4167 | BX7: 2930.4167 | BY7: 2930.4167 | BZ7: 2930.4167 | CA7: 2930.4167 | CB7: 2930.4167 | CC7: 2930.4167 | CD7: 2930.4167 | CE7: 2930.4167 | CF7: 2930.4167 | CG7: 2930.4167 | CH7: 2930.4167 | CI7: 2930.4167 | CJ7: 2930.4167 | CK7: 2930.4167 | CL7: 2930.4167 | CM7: 2930.4167 | CN7: 2930.4167 | CU7: =SUM(K7:CT7) -> 4261998.4
A8: 2024 | B8: NextTi | C8: 영구 | D8: [Hana Indonesia][Hana K8S 24.04.26] | E8: 24.05.10 | H8: 43820 | J8: Hana - K8S | S8: (영구 라이선스) | T8: 43820 | CU8: =SUM(K8:CT8) -> 43820
A9: 2024 | B9: Triputra | D9: [Smartfren][Smartfren APM SERVER 24.05.30~27.05.30] | E9: 24.05~27.05 | F9: 12 | G9: 50512 | H9: 50512 | J9: Smartfren - APM/Server | R9: 4209.3333 | S9: 4209.3333 | T9: 4209.3333 | U9: 4209.3333 | V9: 4209.3333 | W9: 4209.3333 | X9: 4209.3333 | Y9: 4209.3333 | Z9: 4209.3333 | AA9: 4209.3333 | AB9: 4209.3333 | AC9: 4209.3333 | BL9: 4209.3333 | BM9: 4209.3333 | BN9: 4209.3333 | BO9: 4209.3333 | BP9: 4209.3333 | BQ9: 4209.3333 | BR9: 4209.3333 | BS9: 4209.3333 | BT9: 4209.3333 | BU9: 4209.3333 | BV9: 4209.3333 | BW9: 4209.3333 | BX9: 4209.3333 | BY9: 4209.3333 | BZ9: 4209.3333 | CA9: 4209.3333 | CB9: 4209.3333 | CC9: 4209.3333 | CD9: 4209.3333 | CE9: 4209.3333 | CF9: 4209.3333 | CG9: 4209.3333 | CH9: 4209.3333 | CI9: 4209.3333 | CJ9: 4209.3333 | CK9: 4209.3333 | CL9: 4209.3333 | CU9: =SUM(K9:CT9) -> 164164
A10: 2024 | B10: NextTi | D10: [JTrust][On Prem_SERVER, APM, DB 24.07.31-29.07.31] | E10: 24.07~29.08 | F10: 60 | G10: 12870 | H10: 64350 | J10: Jtrust - Server/APM/DB | U10: 1072.5 | V10: 1072.5 | W10: 1072.5 | X10: 1072.5 | Y10: 1072.5 | Z10: 1072.5 | AA10: 1072.5 | AB10: 1072.5 | AC10: 1072.5 | AD10: 1072.5 | AE10: 1072.5 | AF10: 1072.5 | AG10: 1072.5 | AH10: 1072.5 | AI10: 1072.5 | AJ10: 1072.5 | AK10: 1072.5 | AL10: 1072.5 | AN10: 1072.5 | AO10: 1072.5 | AP10: 1072.5 | AQ10: 1072.5 | AR10: 1072.5 | AS10: 1072.5 | AT10: 1072.5 | AU10: 1072.5 | AV10: 1072.5 | AW10: 1072.5 | AX10: 1072.5 | AY10: 1072.5 | AZ10: 1072.5 | BA10: 1072.5 | BB10: 1072.5 | BC10: 1072.5 | BD10: 1072.5 | BE10: 1072.5 | BF10: 1072.5 | BG10: 1072.5 | BH10: 1072.5 | BI10: 1072.5 | BJ10: 1072.5 | BK10: 1072.5 | BL10: 1072.5 | BM10: 1072.5 | BN10: 1072.5 | BO10: 1072.5 | BP10: 1072.5 | BQ10: 1072.5 | BR10: 1072.5 | BS10: 1072.5 | BT10: 1072.5 | BU10: 1072.5 | BV10: 1072.5 | BW10: 1072.5 | BX10: 1072.5 | BY10: 1072.5 | BZ10: 1072.5 | CA10: 1072.5 | CB10: 1072.5 | CC10: 1072.5 | CU10: =SUM(K10:CT10) -> 64350
A11: 2024 | B11: Triputra | D11: [FIF][SaaS Apm/Server/Db/Npm/Log 24.10.01-26.10.01] | E11: 24.10~26.09 | F11: 24 | G11: 14360 | H11: 28720 | J11: FIF - APM/Server/DB/NPM/Log | X11: 1196.6667 | Y11: 1196.6667 | Z11: 1196.6667 | AA11: 1196.6667 | AB11: 1196.6667 | AC11: 1196.6667 | AD11: 1196.6667 | AE11: 1196.6667 | AF11: 1196.6667 | AG11: 1196.6667 | AH11: 1196.6667 | AI11: 1196.6667 | AJ11: 1196.6667 | AK11: 1196.6667 | AL11: 1196.6667 | AM11: 1590094 | AN11: 1196.6667 | AO11: 1196.6667 | AP11: 1196.6667 | AQ11: 1196.6667 | AR11: 1196.6667 | AS11: 1196.6667 | AT11: 1196.6667 | AU11: 1196.6667 | AV11: 1196.6667 | AW11: 1196.6667 | AX11: 1196.6667 | AY11: 1196.6667 | AZ11: 1196.6667 | BA11: 1196.6667 | BB11: 1196.6667 | BC11: 1196.6667 | BD11: 1196.6667 | BE11: 1196.6667 | BF11: 1196.6667 | BG11: 1196.6667 | BH11: 1196.6667 | BI11: 1196.6667 | BJ11: 1196.6667 | BK11: 1196.6667 | BL11: 1196.6667 | BM11: 1196.6667 | BN11: 1196.6667 | BO11: 1196.6667 | BP11: 1196.6667 | BQ11: 1196.6667 | BR11: 1196.6667 | BS11: 1196.6667 | BT11: 1196.6667 | CU11: =SUM(K11:CT11) -> 1647534
A12: 2025 | B12: Triputra | D12: [Pertalife] [SaaS APM/Server/DB] | E12: 25.06~28.05 | F12: 36 | G12: =H12/3 -> 4263.6667 | H12: 12791 | J12: Pertalife - APM/Server/DB | AE12: 355.30556 | AF12: 355.30556 | AG12: 355.30556 | AH12: 355.30556 | AI12: 355.30556 | AJ12: 355.30556 | AK12: 355.30556 | AL12: 355.30556 | AM12: 484980 | AN12: 355.30556 | AO12: 355.30556 | AP12: 355.30556 | AQ12: 355.30556 | AR12: 355.30556 | AS12: 355.30556 | AT12: 355.30556 | AU12: 355.30556 | AV12: 355.30556 | AW12: 355.30556 | AX12: 355.30556 | AY12: 355.30556 | AZ12: 355.30556 | BA12: 355.30556 | BB12: 355.30556 | BC12: 355.30556 | BD12: 355.30556 | BE12: 355.30556 | BF12: 355.30556 | BG12: 355.30556 | BH12: 355.30556 | BI12: 355.30556 | BJ12: 355.30556 | BK12: 355.30556 | BL12: 355.30556 | BM12: 355.30556 | BN12: 355.30556 | BO12: 355.30556 | BP12: 355.30556 | BQ12: 355.30556 | BR12: 355.30556 | BS12: 355.30556 | BT12: 355.30556 | BU12: 355.30556 | BV12: 355.30556 | BW12: 355.30556 | BX12: 355.30556 | BY12: 355.30556 | BZ12: 355.30556 | CA12: 355.30556 | CB12: 355.30556 | CC12: 355.30556 | CD12: 355.30556 | CE12: 355.30556 | CF12: 355.30556 | CG12: 355.30556 | CH12: 355.30556 | CI12: 355.30556 | CJ12: 355.30556 | CK12: 355.30556 | CL12: 355.30556 | CM12: 355.30556 | CN12: 355.30556 | CO12: 355.30556 | CP12: 355.30556 | CQ12: 355.30556 | CR12: 355.30556 | CS12: 355.30556 | CT12: 355.30556 | CU12: =SUM(K12:CT12) -> 508785.47
A13: 2025 | B13: NextTi | D13: [Bank Sulutgo][On Premise_ Server/App,Kubernetes, DB] | E13: 25.06~28.05 | F13: 36 | G13: =H13/3 -> 27885 | H13: 83655 | J13: Bank Sulutgo - Server/App,Kubernetes, DB | AE13: 2323.75 | AF13: 2323.75 | AG13: 2323.75 | AH13: 2323.75 | AI13: 2323.75 | AJ13: 2323.75 | AK13: 2323.75 | AL13: 2323.75 | AN13: 2323.75 | AO13: 2323.75 | AP13: 2323.75 | AQ13: 2323.75 | AR13: 2323.75 | AS13: 2323.75 | AT13: 2323.75 | AU13: 2323.75 | AV13: 2323.75 | AW13: 2323.75 | AX13: 2323.75 | AY13: 2323.75 | AZ13: 2323.75 | BA13: 2323.75 | BB13: 2323.75 | BC13: 2323.75 | BD13: 2323.75 | BE13: 2323.75 | BF13: 2323.75 | BG13: 2323.75 | BH13: 2323.75 | BI13: 2323.75 | BJ13: 2323.75 | BK13: 2323.75 | BL13: 2323.75 | BM13: 2323.75 | BN13: 2323.75 | BO13: 2323.75 | BP13: 2323.75 | BQ13: 2323.75 | BR13: 2323.75 | BS13: 2323.75 | BT13: 2323.75 | BU13: 2323.75 | BV13: 2323.75 | BW13: 2323.75 | BX13: 2323.75 | BY13: 2323.75 | BZ13: 2323.75 | CA13: 2323.75 | CB13: 2323.75 | CC13: 2323.75 | CD13: 2323.75 | CE13: 2323.75 | CF13: 2323.75 | CG13: 2323.75 | CH13: 2323.75 | CI13: 2323.75 | CJ13: 2323.75 | CK13: 2323.75 | CL13: 2323.75 | CM13: 2323.75 | CN13: 2323.75 | CO13: 2323.75 | CP13: 2323.75 | CQ13: 2323.75 | CR13: 2323.75 | CS13: 2323.75 | CT13: 2323.75 | CU13: =SUM(K13:CT13) -> 155691.25
A14: 2025 | B14: NextTi | D14: [JTrust][BJI_APM,Server,DB_Onpremise_5yr] | E14: 25.06~30.05 | F14: 60 | G14: =H14/5 -> 17597.6 | H14: 87988 | J14: JTrust - APM/Server/DB | AE14: 1466.4667 | AF14: 1466.4667 | AG14: 1466.4667 | AH14: 1466.4667 | AI14: 1466.4667 | AJ14: 1466.4667 | AK14: 1466.4667 | AL14: 1466.4667 | AN14: 1466.4667 | AO14: 1466.4667 | AP14: 1466.4667 | AQ14: 1466.4667 | AR14: 1466.4667 | AS14: 1466.4667 | AT14: 1466.4667 | AU14: 1466.4667 | AV14: 1466.4667 | AW14: 1466.4667 | AX14: 1466.4667 | AY14: 1466.4667 | AZ14: 1466.4667 | BA14: 1466.4667 | BB14: 1466.4667 | BC14: 1466.4667 | BD14: 1466.4667 | BE14: 1466.4667 | BF14: 1466.4667 | BG14: 1466.4667 | BH14: 1466.4667 | BI14: 1466.4667 | BJ14: 1466.4667 | BK14: 1466.4667 | BL14: 1466.4667 | BM14: 1466.4667 | BN14: 1466.4667 | BO14: 1466.4667 | BP14: 1466.4667 | BQ14: 1466.4667 | BR14: 1466.4667 | BS14: 1466.4667 | BT14: 1466.4667 | BU14: 1466.4667 | BV14: 1466.4667 | BW14: 1466.4667 | BX14: 1466.4667 | BY14: 1466.4667 | BZ14: 1466.4667 | CA14: 1466.4667 | CB14: 1466.4667 | CC14: 1466.4667 | CD14: 1466.4667 | CE14: 1466.4667 | CF14: 1466.4667 | CG14: 1466.4667 | CH14: 1466.4667 | CI14: 1466.4667 | CJ14: 1466.4667 | CK14: 1466.4667 | CL14: 1466.4667 | CM14: 1466.4667 | CU14: =SUM(K14:CT14) -> 87988
A15: 2025 | B15: NextTi | D15: [Mirae Asset][Mirae Asset_SaaS_Server,DB_3yr] | E15: 25.05~28.05 | F15: 36 | G15: 8923.2 | H15: 26770 | J15: Mirae Asset - DB/Server | AE15: 743.61111 | AF15: 743.61111 | AG15: 743.61111 | AH15: 743.61111 | AI15: 743.61111 | AJ15: 743.61111 | AK15: 743.61111 | AL15: 743.61111 | AN15: 743.61111 | AO15: 743.61111 | AP15: 743.61111 | AQ15: 743.61111 | AR15: 743.61111 | AS15: 743.61111 | AT15: 743.61111 | AU15: 743.61111 | AV15: 743.61111 | AW15: 743.61111 | AX15: 743.61111 | AY15: 743.61111 | AZ15: 743.61111 | BA15: 743.61111 | BB15: 743.61111 | BC15: 743.61111 | BD15: 743.61111 | BE15: 743.61111 | BF15: 743.61111 | BG15: 743.61111 | BH15: 743.61111 | BI15: 743.61111 | BJ15: 743.61111 | BK15: 743.61111 | BL15: 743.61111 | BM15: 743.61111 | BN15: 743.61111 | BO15: 743.61111 | BP15: 743.61111 | BQ15: 743.61111 | BR15: 743.61111 | BS15: 743.61111 | BT15: 743.61111 | BU15: 743.61111 | BV15: 743.61111 | BW15: 743.61111 | BX15: 743.61111 | BY15: 743.61111 | BZ15: 743.61111 | CA15: 743.61111 | CB15: 743.61111 | CC15: 743.61111 | CD15: 743.61111 | CE15: 743.61111 | CF15: 743.61111 | CG15: 743.61111 | CH15: 743.61111 | CI15: 743.61111 | CJ15: 743.61111 | CK15: 743.61111 | CL15: 743.61111 | CM15: 743.61111 | CN15: 743.61111 | CO15: 743.61111 | CP15: 743.61111 | CQ15: 743.61111 | CR15: 743.61111 | CS15: 743.61111 | CT15: 743.61111 | CU15: =SUM(K15:CT15) -> 49821.944
A16: 2025 | B16: Triputra | C16: 영구 | D16: [BCAF][BCAF_Onprem_APM,Server,DB] | E16: 25.07~28.07 | F16: 36 | G16: 4158 | H16: 12474 | J16: BCAF - APM/Server/DB | AF16: 346.5 | AG16: 346.5 | AH16: 346.5 | AI16: 346.5 | AJ16: 346.5 | AK16: 346.5 | AL16: 346.5 | AM16: =393913+39391+39391 -> 472695 | AN16: 346.5 | AO16: 346.5 | AP16: 346.5 | AQ16: 346.5 | AR16: 346.5 | AS16: 346.5 | AT16: 346.5 | AU16: 346.5 | AV16: 346.5 | AW16: 346.5 | AX16: 346.5 | AY16: 346.5 | AZ16: 346.5 | BA16: 346.5 | BB16: 346.5 | BC16: 346.5 | BD16: 346.5 | BE16: 346.5 | BF16: 346.5 | BG16: 346.5 | BH16: 346.5 | BI16: 346.5 | BJ16: 346.5 | BK16: 346.5 | BL16: 346.5 | BM16: 346.5 | BN16: 346.5 | BO16: 346.5 | BP16: 346.5 | BQ16: 346.5 | BR16: 346.5 | BS16: 346.5 | BT16: 346.5 | BU16: 346.5 | BV16: 346.5 | BW16: 346.5 | BX16: 346.5 | BY16: 346.5 | BZ16: 346.5 | CA16: 346.5 | CB16: 346.5 | CC16: 346.5 | CD16: 346.5 | CE16: 346.5 | CF16: 346.5 | CG16: 346.5 | CH16: 346.5 | CI16: 346.5 | CJ16: 346.5 | CK16: 346.5 | CL16: 346.5 | CM16: 346.5 | CN16: 346.5 | CO16: 346.5 | CP16: 346.5 | CQ16: 346.5 | CR16: 346.5 | CS16: 346.5 | CT16: 346.5 | CU16: =SUM(K16:CT16) -> 495564
A17: 2025 | B17: Triputra | C17: 영구 | D17: [Simas Jiwa][SimasJiwa_Arete_Server,DB] | E17: 25.08~28.08 | F17: 36 | G17: 4455 | H17: 13365 | J17: SimasJiwa_Arete - Server/DB | AG17: 371.25 | AH17: 371.25 | AI17: 371.25 | AJ17: 371.25 | AK17: 371.25 | AL17: 371.25 | AM17: =518153 -> 518153 | AN17: 371.25 | AO17: 371.25 | AP17: 371.25 | AQ17: 371.25 | AR17: 371.25 | AS17: 371.25 | AT17: 371.25 | AU17: 371.25 | AV17: 371.25 | AW17: 371.25 | AX17: 371.25 | AY17: 371.25 | AZ17: 371.25 | BA17: 371.25 | BB17: 371.25 | BC17: 371.25 | BD17: 371.25 | BE17: 371.25 | BF17: 371.25 | BG17: 371.25 | BH17: 371.25 | BI17: 371.25 | BJ17: 371.25 | BK17: 371.25 | BL17: 371.25 | BM17: 371.25 | BN17: 371.25 | BO17: 371.25 | BP17: 371.25 | BQ17: 371.25 | BR17: 371.25 | BS17: 371.25 | BT17: 371.25 | BU17: 371.25 | BV17: 371.25 | BW17: 371.25 | BX17: 371.25 | BY17: 371.25 | BZ17: 371.25 | CA17: 371.25 | CB17: 371.25 | CC17: 371.25 | CD17: 371.25 | CE17: 371.25 | CF17: 371.25 | CG17: 371.25 | CH17: 371.25 | CI17: 371.25 | CJ17: 371.25 | CK17: 371.25 | CL17: 371.25 | CM17: 371.25 | CN17: 371.25 | CO17: 371.25 | CP17: 371.25 | CQ17: 371.25 | CR17: 371.25 | CS17: 371.25 | CT17: 371.25 | CU17: =SUM(K17:CT17) -> 542284.25
A18: 2025 | B18: Next TI | D18: [JTrust][BJI_APM_Additional_Onpremise_5yr] | E18: 25.09~30.09 | F18: 60 | G18: =H18/5 -> 4928.4 | H18: 24642 | J18: Bank JTrust Indonesia - APM | AH18: 410.7 | AI18: 410.7 | AJ18: 410.7 | AK18: 410.7 | AL18: 410.7 | AN18: 410.7 | AO18: 410.7 | AP18: 410.7 | AQ18: 410.7 | AR18: 410.7 | AS18: 410.7 | AT18: 410.7 | AU18: 410.7 | AV18: 410.7 | AW18: 410.7 | AX18: 410.7 | AY18: 410.7 | AZ18: 410.7 | BA18: 410.7 | BB18: 410.7 | BC18: 410.7 | BD18: 410.7 | BE18: 410.7 | BF18: 410.7 | BG18: 410.7 | BH18: 410.7 | BI18: 410.7 | BJ18: 410.7 | BK18: 410.7 | BL18: 410.7 | BM18: 410.7 | BN18: 410.7 | BO18: 410.7 | BP18: 410.7 | BQ18: 410.7 | BR18: 410.7 | BS18: 410.7 | BT18: 410.7 | BU18: 410.7 | BV18: 410.7 | BW18: 410.7 | BX18: 410.7 | BY18: 410.7 | BZ18: 410.7 | CA18: 410.7 | CB18: 410.7 | CC18: 410.7 | CD18: 410.7 | CE18: 410.7 | CF18: 410.7 | CG18: 410.7 | CH18: 410.7 | CI18: 410.7 | CJ18: 410.7 | CK18: 410.7 | CL18: 410.7 | CM18: 410.7 | CN18: 410.7 | CO18: 410.7 | CP18: 410.7 | CU18: =SUM(K18:CT18) -> 24642
A19: 2025 | B19: Triputra | C19: 영구 | D19: [Panin Bank][Panin Bank_Skyworx_APM] | E19: 25.09~30.09 | F19: 60 | G19: =H19/5 -> 5068.8 | H19: 25344 | J19: Panin Bank_Skyworx_APM | AH19: =$H$19/60 -> 422.4 | AI19: =$H$19/60 -> 422.4 | AJ19: =$H$19/60 -> 422.4 | AK19: =$H$19/60 -> 422.4 | AL19: =$H$19/60 -> 422.4 | AM19: 592287 | AN19: =$H$19/60 -> 422.4 | AO19: =$H$19/60 -> 422.4 | AP19: =$H$19/60 -> 422.4 | AQ19: =$H$19/60 -> 422.4 | AR19: =$H$19/60 -> 422.4 | AS19: =$H$19/60 -> 422.4 | AT19: =$H$19/60 -> 422.4 | AU19: =$H$19/60 -> 422.4 | ... CP19: =$H$19/60 -> 422.4 | CU19: =SUM(K19:CT19) -> 617631
A20: 2025 | B20: Triputra | D20: [Cimb Niaga][Cimb Niaga Indonesia_Skyworx_APM] | E20: 25.09~30.09 | F20: 60 | G20: =H20/5 -> 2273.7 | H20: 11368.5 | J20: Cimb Niaga Indonesia_Skyworx_APM | AH20: =$H$20/60 -> 189.475 | AI20: =$H$20/60 -> 189.475 | AJ20: =$H$20/60 -> 189.475 | AK20: =$H$20/60 -> 189.475 | AL20: =$H$20/60 -> 189.475 | AM20: 265680 | AN20: =$H$20/60 -> 189.475 | AO20: =$H$20/60 -> 189.475 | AP20: =$H$20/60 -> 189.475 | AQ20: =$H$20/60 -> 189.475 | AR20: =$H$20/60 -> 189.475 | AS20: =$H$20/60 -> 189.475 | AT20: =$H$20/60 -> 189.475 | AU20: =$H$20/60 -> 189.475 | ... CP20: =$H$20/60 -> 189.475 | CU20: =SUM(K20:CT20) -> 277048.5
A21: 2025 | B21: Triputra | D21: [KlikIndomaret][Klikindomaret_BestChoice_K8s] | E21: 25.11~27.11 | F21: 24 | G21: 14850 | H21: 29700 | J21: Klikindomaret_BestChoice_K8s | AJ21: 1238 | AK21: 1238 | AL21: 1238 | AM21: 1788930 | AN21: 1238 | AO21: 1238 | AP21: 1238 | AQ21: 1238 | AR21: 1238 | AS21: 1238 | AT21: 1238 | AU21: 1238 | AV21: 1238 | AW21: 1238 | AX21: 1238 | AY21: 1238 | AZ21: 1238 | BA21: 1238 | BB21: 1238 | BC21: 1238 | BD21: 1238 | BE21: 1238 | BF21: 1238 | BG21: 1238 | BH21: 1238 | BI21: 1238 | BJ21: 1238 | BK21: 1238 | BL21: 1238 | BM21: 1238 | BN21: 1238 | BO21: 1238 | BP21: 1238 | BQ21: 1238 | BR21: 1238 | BS21: 1238 | BT21: 1238 | BU21: 1238 | BV21: 1238 | BW21: 1238 | BX21: 1238 | BY21: 1238 | BZ21: 1238 | CA21: 1238 | CB21: 1238 | CC21: 1238 | CD21: 1238 | CE21: 1238 | CF21: 1238 | CU21: =SUM(K21:CT21) -> 1848354
A22: 2025 | B22: ABDistributing | D22: [HyundaiTransys][Hyundai Transys_ABdistributing_DBM] | E22: 25.11~26.11 | F22: 12 | G22: 7780 | H22: 7780 | J22: Hyundai Transys_ABdistributing_DBM | AJ22: 648 | AK22: 648 | AL22: 648 | AN22: 648 | AO22: 648 | AP22: 648 | AQ22: 648 | AR22: 648 | AS22: 648 | AT22: 648 | AU22: 648 | AV22: 648 | AW22: 648 | AX22: 648 | AY22: 648 | AZ22: 648 | BA22: 648 | BB22: 648 | BC22: 648 | BD22: 648 | BE22: 648 | BF22: 648 | BG22: 648 | BH22: 648 | BI22: 648 | BJ22: 648 | BK22: 648 | BL22: 648 | BM22: 648 | BN22: 648 | BO22: 648 | BP22: 648 | BQ22: 648 | BR22: 648 | BS22: 648 | BT22: 648 | BU22: 648 | BV22: 648 | BW22: 648 | BX22: 648 | BY22: 648 | BZ22: 648 | CA22: 648 | CB22: 648 | CC22: 648 | CD22: 648 | CE22: 648 | CF22: 648 | CG22: 648 | CH22: 648 | CI22: 648 | CJ22: 648 | CK22: 648 | CL22: 648 | CM22: 648 | CN22: 648 | CO22: 648 | CP22: 648 | CQ22: 648 | CR22: 648 | CU22: =SUM(K22:CT22) -> 38880
A23: 2025 | B23: Triputra | D23: [FIF][Phase 1 Renewal_On Prem_K8S, Log] | E23: 25.12.19~27.12.19 | F23: 24 | G23: 2579 | H23: 5160 | J23: FIF Renewal | AL23: 214.96 | AM23: 317837 | AN23: 214.96 | AO23: 214.96 | AP23: 214.96 | AQ23: 214.96 | AR23: 214.96 | AS23: 214.96 | AT23: 214.96 | AU23: 214.96 | AV23: 214.96 | AW23: 214.96 | AX23: 214.96 | AY23: 214.96 | AZ23: 214.96 | BA23: 214.96 | BB23: 214.96 | BC23: 214.96 | BD23: 214.96 | BE23: 214.96 | BF23: 214.96 | BG23: 214.96 | BH23: 214.96 | BI23: 214.96 | BJ23: 214.96 | BK23: 214.96 | BL23: 214.96 | BM23: 214.96 | BN23: 214.96 | BO23: 214.96 | BP23: 214.96 | BQ23: 214.96 | BR23: 214.96 | BS23: 214.96 | BT23: 214.96 | BU23: 214.96 | BV23: 214.96 | BW23: 214.96 | BX23: 214.96 | BY23: 214.96 | BZ23: 214.96 | CA23: 214.96 | CB23: 214.96 | CC23: 214.96 | CD23: 214.96 | CE23: 214.96 | CF23: 214.96 | CG23: 214.96 | CH23: 214.96 | CI23: 214.96 | CJ23: 214.96 | CK23: 214.96 | CL23: 214.96 | CM23: 214.96 | CN23: 214.96 | CO23: 214.96 | CP23: 214.96 | CQ23: 214.96 | CR23: 214.96 | CS23: 214.96 | CT23: 214.96 | CU23: =SUM(K23:CT23) -> 330734.6
A24: 2025 | B24: Triputra | D24: [Indofood][On Prem_APM_Server_DB] | E24: 25.12.19~28.12.19 | F24: 36 | G24: 4950 | H24: 14850 | J24: Indofood | AK24: 412 | AL24: 412 | AM24: 609345 | AN24: 412 | AO24: 412 | AP24: 412 | AQ24: 412 | AR24: 412 | AS24: 412 | AT24: 412 | AU24: 412 | AV24: 412 | AW24: 412 | AX24: 412 | AY24: 412 | AZ24: 412 | BA24: 412 | BB24: 412 | BC24: 412 | BD24: 412 | BE24: 412 | BF24: 412 | BG24: 412 | BH24: 412 | BI24: 412 | BJ24: 412 | BK24: 412 | BL24: 412 | BM24: 412 | BN24: 412 | BO24: 412 | BP24: 412 | BQ24: 412 | BR24: 412 | BS24: 412 | BT24: 412 | BU24: 412 | BV24: 412 | BW24: 412 | BX24: 412 | BY24: 412 | BZ24: 412 | CA24: 412 | CB24: 412 | CC24: 412 | CD24: 412 | CE24: 412 | CF24: 412 | CG24: 412 | CH24: 412 | CI24: 412 | CJ24: 412 | CK24: 412 | CL24: 412 | CM24: 412 | CN24: 412 | CO24: 412 | CP24: 412 | CQ24: 412 | CR24: 412 | CS24: 412 | CT24: 412 | CU24: =SUM(K24:CT24) -> 634477
A25: 2025 | B25: Triputra | D25: [Katadata][SaaS_APM, K8s] | E25: 25.12.23~28.12.23 | F25: 36 | G25: 7497.6 | H25: 22492.8 | J25: Katadata | AK25: 624.8 | AL25: 624.8 | AM25: 924015 | AN25: 624.8 | AO25: 624.8 | AP25: 624.8 | AQ25: 624.8 | AR25: 624.8 | AS25: 624.8 | AT25: 624.8 | AU25: 624.8 | AV25: 624.8 | AW25: 624.8 | AX25: 624.8 | AY25: 624.8 | AZ25: 624.8 | BA25: 624.8 | BB25: 624.8 | BC25: 624.8 | BD25: 624.8 | BE25: 624.8 | BF25: 624.8 | BG25: 624.8 | BH25: 624.8 | BI25: 624.8 | BJ25: 624.8 | BK25: 624.8 | BL25: 624.8 | BM25: 624.8 | BN25: 624.8 | BO25: 624.8 | BP25: 624.8 | BQ25: 624.8 | BR25: 624.8 | BS25: 624.8 | BT25: 624.8 | BU25: 624.8 | BV25: 624.8 | BW25: 624.8 | BX25: 624.8 | BY25: 624.8 | BZ25: 624.8 | CA25: 624.8 | CB25: 624.8 | CC25: 624.8 | CD25: 624.8 | CE25: 624.8 | CF25: 624.8 | CG25: 624.8 | CH25: 624.8 | CI25: 624.8 | CJ25: 624.8 | CK25: 624.8 | CL25: 624.8 | CM25: 624.8 | CN25: 624.8 | CO25: 624.8 | CP25: 624.8 | CQ25: 624.8 | CR25: 624.8 | CS25: 624.8 | CT25: 624.8 | CU25: =SUM(K25:CT25) -> 962127.8
A26: 2026 | B26: Triputra | D26: Smartfren Renewal | E26: 26.01~28.01 | F26: 24 | G26: 55562.76 | H26: 111125.52 | J26: Smartfren Renewal | AL26: 4630 | AM26: =5682836+1136567 -> 6819403 | AN26: 4630.23 | AO26: 4630.23 | AP26: 4630.23 | AQ26: 4630.23 | AR26: 4630.23 | AS26: 4630.23 | AT26: 4630.23 | AU26: 4630.23 | AV26: 4630.23 | AW26: 4630.23 | AX26: 4630.23 | AY26: 4630.23 | AZ26: 4630.23 | BA26: 4630.23 | BB26: 4630.23 | BC26: 4630.23 | BD26: 4630.23 | BE26: 4630.23 | BF26: 4630.23 | BG26: 4630.23 | BH26: 4630.23 | BI26: 4630.23 | BJ26: 4630.23 | BK26: 4630.23
A27: 2026 | B27: Triputra | D27: Adira Phase 2 | E27: 26.02.03~29.02 | F27: 36 | G27: 14256 | H27: 42768 | J27: Adira Phase 2 | AN27: 1188 | AO27: 1188 | AP27: 1188 | AQ27: 1188 | AR27: 1188 | AS27: 1188 | AT27: 1188 | AU27: 1188 | AV27: 1188 | AW27: 1188 | AX27: 1188 | AY27: 1188 | AZ27: 1188 | BA27: 1188 | BB27: 1188 | BC27: 1188 | BD27: 1188 | BE27: 1188 | BF27: 1188 | BG27: 1188 | BH27: 1188 | BI27: 1188 | BJ27: 1188 | BK27: 1188 | BL27: 1188 | BM27: 1188 | BN27: 1188 | BO27: 1188 | BP27: 1188 | BQ27: 1188 | BR27: 1188 | BS27: 1188 | BT27: 1188 | BU27: 1188 | BV27: 1188 | BW27: 1188 | BX27: 1188 | BY27: 1188 | BZ27: 1188 | CA27: 1188 | CB27: 1188 | CC27: 1188 | CD27: 1188 | CE27: 1188 | CF27: 1188 | CG27: 1188 | CH27: 1188 | CI27: 1188 | CJ27: 1188 | CK27: 1188 | CL27: 1188 | CM27: 1188 | CN27: 1188 | CO27: 1188 | CP27: 1188 | CQ27: 1188 | CR27: 1188 | CS27: 1188 | CT27: 1188 | CU27: =SUM(K27:CT27) -> 70092
A28: 2026 | B28: Triputra | D28: Indopaket | E28: 26.02.16~28.02.16 | F28: 24 | G28: 8316 | H28: 16632 | J28: Indopaket | AO28: 693 | AP28: 693 | AQ28: 693 | AR28: 693 | AS28: 693 | AT28: 693 | AU28: 693 | AV28: 693 | AW28: 693 | AX28: 693 | AY28: 693 | AZ28: 693 | BA28: 693 | BB28: 693 | BC28: 693 | BD28: 693 | BE28: 693 | BF28: 693 | BG28: 693 | BH28: 693 | BI28: 693 | BJ28: 693 | BK28: 693 | BL28: 693 | BM28: 693 | BN28: 693 | BO28: 693 | BP28: 693 | BQ28: 693 | BR28: 693 | BS28: 693 | BT28: 693 | BU28: 693 | BV28: 693 | BW28: 693 | BX28: 693 | BY28: 693 | BZ28: 693 | CA28: 693 | CB28: 693 | CC28: 693 | CD28: 693 | CE28: 693 | CF28: 693 | CG28: 693 | CH28: 693 | CI28: 693 | CJ28: 693 | CK28: 693 | CL28: 693 | CM28: 693 | CN28: 693 | CO28: 693 | CP28: 693 | CQ28: 693 | CR28: 693 | CS28: 693 | CT28: 693 | CU28: =SUM(K28:CT28) -> 40194
A29: 2026 | B29: Triputra | D29: Sinarmas Hana Finance | E29: 26.02.19~27.02.19 | F29: 24 | G29: 280.5 | H29: 280.5 | J29: Indopaket | AO29: 23.38 | AP29: 23.38 | AQ29: 23.38 | AR29: 23.38 | AS29: 23.38 | AT29: 23.38 | AU29: 23.38 | AV29: 23.38 | AW29: 23.38 | AX29: 23.38 | AY29: 23.38 | AZ29: 23.38 | BA29: 23.38 | BB29: 23.38 | BC29: 23.38 | BD29: 23.38 | BE29: 23.38 | BF29: 23.38 | BG29: 23.38 | BH29: 23.38 | BI29: 23.38 | BJ29: 23.38 | BK29: 23.38 | BL29: 23.38 | BM29: 23.38 | BN29: 23.38 | BO29: 23.38 | BP29: 23.38 | BQ29: 23.38 | BR29: 23.38 | BS29: 23.38 | BT29: 23.38 | BU29: 23.38 | BV29: 23.38 | BW29: 23.38 | BX29: 23.38 | BY29: 23.38 | BZ29: 23.38 | CA29: 23.38 | CB29: 23.38 | CC29: 23.38 | CD29: 23.38 | CE29: 23.38 | CF29: 23.38 | CG29: 23.38 | CH29: 23.38 | CI29: 23.38 | CJ29: 23.38 | CK29: 23.38 | CL29: 23.38 | CM29: 23.38 | CN29: 23.38 | CO29: 23.38 | CP29: 23.38 | CQ29: 23.38 | CR29: 23.38 | CS29: 23.38 | CT29: 23.38 | CU29: =SUM(K29:CT29) -> 1356.04
A30: 2026 | B30: Triputra | D30: [Tempo Scan][On Prem_APM] | E30: 25.12.17~ | F30: 36 | G30: 14887 | H30: 44663 | J30: Tempo Scan | AK30: 1240 | AL30: 1240 | AN30: 1240 | AO30: 1240 | AP30: 1240 | AQ30: 1240 | AR30: 1240 | AS30: 1240 | AT30: 1240 | AU30: 1240 | AV30: 1240 | AW30: 1240 | AX30: 1240 | AY30: 1240 | AZ30: 1240 | BA30: 1240 | BB30: 1240 | BC30: 1240 | BD30: 1240 | BE30: 1240 | BF30: 1240 | BG30: 1240 | BH30: 1240 | BI30: 1240 | BJ30: 1240 | BK30: 1240 | BL30: 1240 | BM30: 1240 | BN30: 1240 | BO30: 1240 | BP30: 1240 | BQ30: 1240 | BR30: 1240 | BS30: 1240 | BT30: 1240 | BU30: 1240 | BV30: 1240 | BW30: 1240 | BX30: 1240 | BY30: 1240 | BZ30: 1240 | CA30: 1240 | CB30: 1240 | CC30: 1240 | CD30: 1240 | CE30: 1240 | CF30: 1240 | CG30: 1240 | CH30: 1240 | CI30: 1240 | CJ30: 1240 | CK30: 1240 | CL30: 1240 | CM30: 1240 | CN30: 1240 | CO30: 1240 | CP30: 1240 | CQ30: 1240 | CR30: 1240 | CS30: 1240 | CT30: 1240 | CU30: =SUM(K30:CT30) -> 75640
A31: 2026 | B31: Triputra | D31: [XLSmart][On Prem_Phase 2 (Over usage)] | E31: 25.12.17~ 26.12.17 | F31: 12 | G31: 20250 | H31: 20250 | J31: Smartfren Phase 2 | AK31: 1687 | AL31: 1687 | AN31: 1687 | AO31: 1687 | AP31: 1687 | AQ31: 1687 | AR31: 1687 | AS31: 1687 | AT31: 1687 | AU31: 1687 | AV31: 1687 | AW31: 1687 | AX31: 1687 | AY31: 1687 | AZ31: 1687 | BA31: 1687 | BB31: 1687 | BC31: 1687 | BD31: 1687 | BE31: 1687 | BF31: 1687 | BG31: 1687 | BH31: 1687 | BI31: 1687 | BJ31: 1687 | BK31: 1687 | BL31: 1687 | BM31: 1687 | BN31: 1687 | BO31: 1687 | BP31: 1687 | BQ31: 1687 | BR31: 1687 | BS31: 1687 | BT31: 1687 | BU31: 1687 | BV31: 1687 | BW31: 1687 | BX31: 1687 | BY31: 1687 | BZ31: 1687 | CA31: 1687 | CB31: 1687 | CC31: 1687 | CD31: 1687 | CE31: 1687 | CF31: 1687 | CG31: 1687 | CU31: =SUM(K31:CT31) -> 80976
A32: 2026 | B32: Triputra | D32: Deal Q1 | E32: 26.03~29.02 | F32: 36 | G32: 40000 | H32: 120000 | J32: Deal Q1 | AO32: 3333 | AP32: 3333 | AQ32: 3333 | AR32: 3333 | AS32: 3333 | AT32: 3333 | AU32: 3333 | AV32: 3333 | AW32: 3333 | AX32: 3333 | AY32: 3333 | AZ32: 3333 | BA32: 3333 | BB32: 3333 | BC32: 3333 | BD32: 3333 | BE32: 3333 | BF32: 3333 | BG32: 3333 | BH32: 3333 | BI32: 3333 | BJ32: 3333 | BK32: 3333 | BL32: 3333 | BM32: 3333 | BN32: 3333 | BO32: 3333 | BP32: 3333 | BQ32: 3333 | BR32: 3333 | BS32: 3333 | BT32: 3333 | BU32: 3333 | BV32: 3333 | BW32: 3333 | BX32: 3333 | CU32: =SUM(K32:CT32) -> 119988
A33: 2026 | B33: Triputra | D33: Deal Q2 | E33: 26.06~29.05 | F33: 36 | G33: 120000 | H33: 360000 | J33: Deal Q2 | AR33: 10000 | AS33: 10000 | AT33: 10000 | AU33: 10000 | AV33: 10000 | AW33: 10000 | AX33: 10000 | AY33: 10000 | AZ33: 10000 | BA33: 10000 | BB33: 10000 | BC33: 10000 | BD33: 10000 | BE33: 10000 | BF33: 10000 | BG33: 10000 | BH33: 10000 | BI33: 10000 | BJ33: 10000 | BK33: 10000 | BL33: 10000 | BM33: 10000 | BN33: 10000 | BO33: 10000 | BP33: 10000 | BQ33: 10000 | BR33: 10000 | BS33: 10000 | BT33: 10000 | BU33: 10000 | BV33: 10000 | BW33: 10000 | BX33: 10000 | BY33: 10000 | BZ33: 10000 | CA33: 10000 | CU33: =SUM(K33:CT33) -> 360000
A34: 2026 | B34: Triputra | D34: Deal Q3 | E34: 26.08~29.07 | F34: 36 | G34: 120000 | H34: 360000 | J34: Deal Q3 | AT34: 10000 | AU34: 10000 | AV34: 10000 | AW34: 10000 | AX34: 10000 | AY34: 10000 | AZ34: 10000 | BA34: 10000 | BB34: 10000 | BC34: 10000 | BD34: 10000 | BE34: 10000 | BF34: 10000 | BG34: 10000 | BH34: 10000 | BI34: 10000 | BJ34: 10000 | BK34: 10000 | BL34: 10000 | BM34: 10000 | BN34: 10000 | BO34: 10000 | BP34: 10000 | BQ34: 10000 | BR34: 10000 | BS34: 10000 | BT34: 10000 | BU34: 10000 | BV34: 10000 | BW34: 10000 | BX34: 10000 | BY34: 10000 | BZ34: 10000 | CA34: 10000 | CB34: 10000 | CC34: 10000 | CU34: =SUM(K34:CT34) -> 360000
A35: 2026 | B35: Triputra | D35: Deal Q4 | E35: 26.11~29.10 | F35: 36 | G35: 120000 | H35: 360000 | J35: Deal Q4 | AW35: 10000 | AX35: 10000 | AY35: 10000 | AZ35: 10000 | BA35: 10000 | BB35: 10000 | BC35: 10000 | BD35: 10000 | BE35: 10000 | BF35: 10000 | BG35: 10000 | BH35: 10000 | BI35: 10000 | BJ35: 10000 | BK35: 10000 | BL35: 10000 | BM35: 10000 | BN35: 10000 | BO35: 10000 | BP35: 10000 | BQ35: 10000 | BR35: 10000 | BS35: 10000 | BT35: 10000 | BU35: 10000 | BV35: 10000 | BW35: 10000 | BX35: 10000 | BY35: 10000 | BZ35: 10000 | CA35: 10000 | CB35: 10000 | CC35: 10000 | CD35: 10000 | CE35: 10000 | CF35: 10000 | CU35: =SUM(K35:CT35) -> 360000
A36: 2027 | B36: Triputra | D36: Deal Q1 | E36: 27.02~30.01 | F36: 36 | G36: 50000 | H36: 150000 | J36: Deal Q1 | AZ36: 4167 | BA36: 4167 | BB36: 4167 | BC36: 4167 | BD36: 4167 | BE36: 4167 | BF36: 4167 | BG36: 4167 | BH36: 4167 | BI36: 4167 | BJ36: 4167 | BK36: 4167 | BL36: 4167 | BM36: 4167 | BN36: 4167 | BO36: 4167 | BP36: 4167 | BQ36: 4167 | BR36: 4167 | BS36: 4167 | BT36: 4167 | BU36: 4167 | BV36: 4167 | BW36: 4167 | BX36: 4167 | BY36: 4167 | BZ36: 4167 | CA36: 4167 | CB36: 4167 | CC36: 4167 | CD36: 4167 | CE36: 4167 | CF36: 4167 | CG36: 4167 | CH36: 4167 | CI36: 4167 | CU36: =SUM(K36:CT36) -> 150012
A37: 2027 | B37: Triputra | D37: Deal Q2 | E37: 27.05~30.04 | F37: 36 | G37: 150000 | H37: 450000 | J37: Deal Q2 | BC37: 12500 | BD37: 12500 | BE37: 12500 | BF37: 12500 | BG37: 12500 | BH37: 12500 | BI37: 12500 | BJ37: 12500 | BK37: 12500 | BL37: 12500 | BM37: 12500 | BN37: 12500 | BO37: 12500 | BP37: 12500 | BQ37: 12500 | BR37: 12500 | BS37: 12500 | BT37: 12500 | BU37: 12500 | BV37: 12500 | BW37: 12500 | BX37: 12500 | BY37: 12500 | BZ37: 12500 | CA37: 12500 | CB37: 12500 | CC37: 12500 | CD37: 12500 | CE37: 12500 | CF37: 12500 | CG37: 12500 | CH37: 12500 | CI37: 12500 | CJ37: 12500 | CK37: 12500 | CL37: 12500 | CU37: =SUM(K37:CT37) -> 450000
A38: 2027 | B38: Triputra | D38: Deal Q3 | E38: 27.09~30.08 | F38: 36 | G38: 150000 | H38: 450000 | J38: Deal Q3 | BG38: 12500 | BH38: 12500 | BI38: 12500 | BJ38: 12500 | BK38: 12500 | BL38: 12500 | BM38: 12500 | BN38: 12500 | BO38: 12500 | BP38: 12500 | BQ38: 12500 | BR38: 12500 | BS38: 12500 | BT38: 12500 | BU38: 12500 | BV38: 12500 | BW38: 12500 | BX38: 12500 | BY38: 12500 | BZ38: 12500 | CA38: 12500 | CB38: 12500 | CC38: 12500 | CD38: 12500 | CE38: 12500 | CF38: 12500 | CG38: 12500 | CH38: 12500 | CI38: 12500 | CJ38: 12500 | CK38: 12500 | CL38: 12500 | CM38: 12500 | CN38: 12500 | CO38: 12500 | CP38: 12500 | CU38: =SUM(K38:CT38) -> 450000
A39: 2027 | B39: Triputra | D39: Deal Q4 | E39: 27.12~30.11 | F39: 36 | G39: 150000 | H39: 450000 | J39: Deal Q4 | BJ39: 12500 | BK39: 12500 | BL39: 12500 | BM39: 12500 | BN39: 12500 | BO39: 12500 | BP39: 12500 | BQ39: 12500 | BR39: 12500 | BS39: 12500 | BT39: 12500 | BU39: 12500 | BV39: 12500 | BW39: 12500 | BX39: 12500 | BY39: 12500 | BZ39: 12500 | CA39: 12500 | CB39: 12500 | CC39: 12500 | CD39: 12500 | CE39: 12500 | CF39: 12500 | CG39: 12500 | CH39: 12500 | CI39: 12500 | CJ39: 12500 | CK39: 12500 | CL39: 12500 | CM39: 12500 | CN39: 12500 | CO39: 12500 | CP39: 12500 | CQ39: 12500 | CR39: 12500 | CS39: 12500 | CU39: =SUM(K39:CT39) -> 450000
A40: 2028 | D40: Deal Q1 | E40: 28.02~31.01 | F40: 36 | G40: 70000 | H40: =G40*3 -> 210000 | CU40: =SUM(K40:CT40) -> 0
...

Sheet 손익계산서(월별)
A1: 한국법인
A2: 과목 | B2: 계 | C2: 1월 | D2: 2월 | E2: 3월 | F2: 4월 | G2: 5월 | H2: 6월 | I2: 7월 | J2: 8월 | K2: 9월 | L2: 10월 | M2: 11월 | N2: 12월
A3: Ⅰ . 매 출 액 2025년 | B3: =SUM(C3:N3) -> 155057165 | C3: 14912353 | D3: 14912353 | E3: 15013851 | F3: 14963102 | G3: 14963093 | H3: 9643014 | I3: 10115663 | J3: 10633820 | K3: 11491828 | L3: 11491779 | M3: 13280715 | N3: 13635594
A4: [4070000] 해외구독(기존) | B4: =SUM(C4:N4) -> 141270022 | C4: 14912353 | D4: 14912353 | E4: 15013851 | F4: 14963102 | G4: 14963093 | H4: 9157984 | I4: 9157984 | J4: 9157984 | K4: 9157984 | L4: 9157984 | M4: 10946920 | N4: 9768430
A5: [4070000] 해외구독(신규) | B5: =SUM(C5:N5) -> 13787143 | C5: 0 | D5: 0 | E5: 0 | F5: 0 | G5: 0 | H5: 485030 | I5: 957679 | J5: 1475836 | K5: 2333844 | L5: 2333795 | M5: 2333795 | N5: 3867164
A7: 미국법인
A8: 과목 | B8: 계 | C8: 1월 | D8: 2월 | E8: 3월 | F8: 4월 | G8: 5월 | H8: 6월 | I8: 7월 | J8: 8월 | K8: 9월 | L8: 10월 | M8: 11월 | N8: 12월
A9: Ⅰ . 매 출 액 2025년 | B9: =SUM(C9:N9) -> 21689889 | C9: =SUM(C10:C11) -> 757109.95 | D9: =SUM(D10:D11) -> 787129.21 | E9: =SUM(E10:E11) -> 841345.72 | F9: =SUM(F10:F11) -> 901507.95 | G9: =SUM(G10:G11) -> 719502.19 | H9: =SUM(H10:H11) -> 934206.94 | I9: =SUM(I10:I11) -> 864271.01 | J9: =SUM(J10:J11) -> 731347.85 | ... N9: =SUM(N10:N11) -> 956461.29
A10: [4070000] 해외구독(기존) | B10: =SUM(C10:N10) -> 10255710 | C10: =516.27*1466.5 -> 757109.95 | D10: =536.74*1466.5 -> 787129.21 | E10: =573.71*1466.5 -> 841345.72 | F10: =626.7*1438.5 -> 901507.95 | G10: =520.85*1381.4 -> 719502.19 | H10: =688.74*1356.4 -> 934206.94 | I10: =624.97*1382.9 -> 864271.01 | J10: =526.68*1388.6 -> 731347.85 | K10: =668.25*1402.2 -> 937020.15 | L10: =616.37*1423.2 -> 877217.78 | M10: =647.59*1464.8 -> 948589.83 | N10: =666.57*1434.9 -> 956461.29
A11: [4090000] 해외영구라이선스 | B11: =SUM(C11:N11) -> 11434180 | C11: 0 | D11: 0 | E11: 0 | F11: 0 | G11: 0 | H11: 0 | I11: 0 | J11: 0 | K11: 0 | L11: 0 | M11: =7781*1469.5 -> 11434180 | N11: 0
A13: 인식x
A14: 과목 | B14: 계 | C14: 1월 | D14: 2월 | E14: 3월 | F14: 4월 | G14: 5월 | H14: 6월 | I14: 7월 | J14: 8월 | K14: 9월 | L14: 10월 | M14: 11월 | N14: 12월
A15: Ⅰ . 매 출 액 2025년 | B15: =SUM(C15:N15) -> 64328487 | C15: =SUM(C16:C18) -> 1484983.5 | D15: =SUM(D16:D18) -> 1484983.5 | E15: =SUM(E16:E18) -> 1484983.5 | F15: =SUM(F16:F18) -> 1484983.5 | G15: =SUM(G16:G18) -> 2512208.1 | H15: =SUM(H16:H18) -> 7653258.6 | I15: =SUM(I16:I18) -> 7653258.6 | J15: =SUM(J16:J18) -> 7653258.6 | ... N15: =SUM(N16:N18) -> 8229142.2
A16: [4070000] 해외구독(기존) | B16: =SUM(C16:N16) -> 17819802 | C16: =($J$27/12*1384.6) -> 1484983.5 | D16: =($J$27/12*1384.6) -> 1484983.5 | E16: =($J$27/12*1384.6) -> 1484983.5 | F16: =($J$27/12*1384.6) -> 1484983.5 | G16: =($J$27/12*1384.6) -> 1484983.5 | H16: =($J$27/12*1384.6) -> 1484983.5 | I16: =($J$27/12*1384.6) -> 1484983.5 | J16: =($J$27/12*1384.6) -> 1484983.5 | ... N16: =($J$27/12*1384.6) -> 1484983.5
A17: [4070000] 해외구독(신규) | B17: =SUM(C17:N17) -> 46508685 | C17: 0 | D17: 0 | E17: 0 | F17: 0 | G17: =($J$28/8*$E$36) -> 1027224.6 | H17: =($J$28/8*$E$36)+(($J$29+$J$30)/7*$G$34) -> 6168275.1 | I17: =($J$28/8*$E$36)+(($J$29+$J$30)/7*$G$34) -> 6168275.1 | J17: =($J$28/8*$E$36)+(($J$29+$J$30)/7*$G$34) -> 6168275.1 | K17: =($J$28/8*$E$36)+(($J$29+$J$30)/7*$G$34)+($J$31/4*$I$34) -> 6744158.7 | L17: =($J$28/8*$E$36)+(($J$29+$J$30)/7*$G$34)+($J$31/4*$I$34) -> 6744158.7 | M17: =($J$28/8*$E$36)+(($J$29+$J$30)/7*$G$34)+($J$31/4*$I$34) -> 6744158.7 | N17: =($J$28/8*$E$36)+(($J$29+$J$30)/7*$G$34)+($J$31/4*$I$34) -> 6744158.7
A19: 취합
A20: 과목 | B20: 계 | C20: 1월 | D20: 2월 | E20: 3월 | F20: 4월 | G20: 5월 | H20: 6월 | I20: 7월 | J20: 8월 | K20: 9월 | L20: 10월 | M20: 11월 | N20: 12월
A21: Ⅰ . 매 출 액 2025년 | B21: =SUM(C21:N21) -> 1.9456686e+08 | C21: =SUM(C22:C23) -> 17154446 | D21: =SUM(D22:D23) -> 17184466 | E21: =SUM(E22:E23) -> 17340180 | F21: =SUM(F22:F23) -> 17349593 | G21: =SUM(G22:G23) -> 17167579 | H21: =SUM(H22:H23) -> 12062204 | I21: =SUM(I22:I23) -> 12464918 | J21: =SUM(J22:J23) -> 12850151 | ... N21: =SUM(N22:N23) -> 16077039
A22: [4070000] 해외구독 | B22: =SUM(C22:N22) -> 1.6934553e+08 | C22: =C4+C10+C16 -> 17154446 | D22: =D4+D10+D16 -> 17184466 | E22: =E4+E10+E16 -> 17340180 | F22: =F4+F10+F16 -> 17349593 | G22: =G4+G10+G16 -> 17167579 | H22: =H4+H10+H16 -> 11577174 | I22: =I4+I10+I16 -> 11507239 | J22: =J4+J10+J16 -> 11374315 | ... N22: =N4+N10+N16 -> 12209875
A23: [4090000] 해외영구라이선스 | B23: =SUM(C23:N23) -> 25221322 | C23: =C5+C11+C18 -> 0 | D23: =D5+D11+D18 -> 0 | E23: =E5+E11+E18 -> 0 | F23: =F5+F11+F18 -> 0 | G23: =G5+G11+G18 -> 0 | H23: =H5+H11+H18 -> 485030 | I23: =I5+I11+I18 -> 957679 | J23: =J5+J11+J18 -> 1475836 | ... N23: =N5+N11+N18 -> 3867164
A26: 분기 | B26: 파트너사 | C26: End User | D26: 매출유형 | E26: 2030년 반영 | F26: 2029년 반영 | G26: 2028년 반영 | H26: 2027년 반영 | I26: 2026년 반영 | J26: 2025년 반영 | K26: 2024년 반영 | M26: 계약금액 | N26: 계약일 | O26: 계약기간 | P26: 비고
A27: 24년 3분기 | B27: Next TI | C27: Jtrust | D27: Private SaaS | F27: 7507 | G27: 12870 | H27: 12870 | I27: 12870 | J27: 12870 | K27: 5363 | M27: 64350 | N27: 45504 | O27: 24/7/31~29/08/31 | P27: 5년 계약,1년단위PO, On-Premise
A28: 25년 2분기 | B28: Next TI | C28: Mirae Asset | D28: Public SaaS | G28: 2974.44 | H28: 8923.33 | I28: 8923.33 | J28: 5948.89 | M28: 26770 | N28: 45778 | O28: 46900 | P28: 3년계약
B29: Next TI | C29: Bank Sulutgo | D29: On-Premise | G29: 11618.75 | H29: 27885 | I29: 27885 | J29: 16266.25 | M29: 83655 | N29: 45834 | O29: 46899 | P29: 3년 계약,On-Premise
B30: Next TI | C30: Bank JTrust | D30: On-Premise | E30: 7332.33 | F30: 17597.6 | G30: 17597.6 | H30: 17597.6 | I30: 17597.6 | J30: 10265.27 | M30: 87988 | N30: 45834 | O30: 47629 | P30: 5년 계약,On-Premise
A31: 24년 3분기 | B31: Next TI | C31: Bank JTrust Indonesia | D31: On-Premise | E31: 3285.6 | F31: 4928.4 | G31: 4928.4 | H31: 4928.4 | I31: 4928.4 | J31: 1642.8 | M31: 24642 | N31: 45922 | O31: 25/9~30/9 | P31: 5년 계약,On-Premise
A34: 환율 | B34: 45657 | C34: 1470 | D34: 45747 | E34: 1466.5 | F34: 45838 | G34: 1356.4 | H34: 45930 | I34: 1402.2 | J34: 46022 | K34: 1434.9
B35: 45688 | C35: 1433.3 | D35: 45777 | E35: 1438.5 | F35: 45869 | G35: 1382.9 | H35: 45961 | I35: 1423.2
B36: 45716 | C36: 1439.6 | D36: 45808 | E36: 1381.4 | F36: 45900 | G36: 1388.6 | H36: 45991 | I36: 1464.8

Sheet Sheet4
A1: Channel | B1: 2026 Q1 | D1: 2026 Q2 | F1: 2026 Q3 | H1: 2026 Q4 | J1: 2026 TTL | L1: 2027 Q1 | N1: 2027 Q2 | P1: 2027 Q3 | R1: 2027 Q4 | T1: 2027 TTL
B2: % | C2: Amount | D2: % | E2: Amount | F2: % | G2: Amount | H2: % | I2: Amount | J2: % | K2: Amount | L2: % | M2: Amount | N2: % | O2: Amount | P2: % | Q2: Amount | R2: % | S2: Amount | T2: % | U2: Amount
A3: Non-FSI (OP) 20% | B3: 10 | C3: 18000 | D3: 30 | E3: 54000 | F3: 30 | G3: 54000 | H3: 30 | I3: 54000 | J3: 100 | K3: 180000 | L3: 10 | M3: 18000 | N3: 30 | O3: 54000 | P3: 30 | Q3: 54000 | R3: 30 | S3: 54000 | T3: 100 | U3: 180000
A4: Non-FSI (SaaS) 20% | B4: 10 | C4: 18000 | D4: 30 | E4: 54000 | F4: 30 | G4: 54000 | H4: 30 | I4: 54000 | J4: 100 | K4: 180000 | L4: 10 | M4: 18000 | N4: 30 | O4: 54000 | P4: 30 | Q4: 54000 | R4: 30 | S4: 54000 | T4: 100 | U4: 180000
A5: FSI 40% | B5: 10 | C5: 36000 | D5: 30 | E5: 108000 | F5: 30 | G5: 108000 | H5: 30 | I5: 108000 | J5: 100 | K5: 360000 | L5: 10 | M5: 36000 | N5: 30 | O5: 108000 | P5: 30 | Q5: 108000 | R5: 30 | S5: 108000 | T5: 100 | U5: 360000
A6: Gov 20% | B6: 10 | C6: 18000 | D6: 30 | E6: 54000 | F6: 30 | G6: 54000 | H6: 30 | I6: 54000 | J6: 100 | K6: 180000 | L6: 10 | M6: 18000 | N6: 30 | O6: 54000 | P6: 30 | Q6: 54000 | R6: 30 | S6: 54000 | T6: 100 | U6: 180000
A7: Grand TTL (ID) | B7: 10 | C7: 90000 | D7: 30 | E7: 270000 | F7: 30 | G7: 270000 | H7: 30 | I7: 270000 | J7: 100 | K7: 900000 | L7: 10 | M7: 90000 | N7: 30 | O7: 270000 | P7: 30 | Q7: 270000 | R7: 30 | S7: 270000 | T7: 100 | U7: 900000
A10: FSI 50% | B10: 10 | C10: 10000 | D10: 30 | E10: 30000 | F10: 30 | G10: 30000 | H10: 30 | I10: 30000 | J10: 100 | K10: 100000 | L10: 10 | M10: 10000 | N10: 30 | O10: 30000 | P10: 30 | Q10: 30000 | R10: 30 | S10: 30000 | T10: 100 | U10: 100000
A11: Gov 50% | B11: 10 | C11: 10000 | D11: 30 | E11: 30000 | F11: 30 | G11: 30000 | H11: 30 | I11: 30000 | J11: 100 | K11: 100000 | L11: 10 | M11: 10000 | N11: 30 | O11: 30000 | P11: 30 | Q11: 30000 | R11: 30 | S11: 30000 | T11: 100 | U11: 100000
A12: Grand TTL (MY) | B12: 10 | C12: 20000 | D12: 30 | E12: 60000 | F12: 30 | G12: 60000 | H12: 30 | I12: 60000 | J12: 100 | K12: 200000 | L12: 10 | M12: 20000 | N12: 30 | O12: 60000 | P12: 30 | Q12: 60000 | R12: 30 | S12: 60000 | T12: 100 | U12: 200000
A15: FSI 50% | B15: 10 | C15: 5000 | D15: 30 | E15: 15000 | F15: 30 | G15: 15000 | H15: 30 | I15: 15000 | J15: 100 | K15: 50000 | L15: 10 | M15: 5000 | N15: 30 | O15: 15000 | P15: 30 | Q15: 15000 | R15: 30 | S15: 15000 | T15: 100 | U15: 50000
A16: Gov 50% | B16: 10 | C16: 5000 | D16: 30 | E16: 15000 | F16: 30 | G16: 15000 | H16: 30 | I16: 15000 | J16: 100 | K16: 50000 | L16: 10 | M16: 5000 | N16: 30 | O16: 15000 | P16: 30 | Q16: 15000 | R16: 30 | S16: 15000 | T16: 100 | U16: 50000
A17: Grand TTL (TH) | B17: 10 | C17: 10000 | D17: 30 | E17: 30000 | F17: 30 | G17: 30000 | H17: 30 | I17: 30000 | J17: 100 | K17: 100000 | L17: 10 | M17: 10000 | N17: 30 | O17: 30000 | P17: 30 | Q17: 30000 | R17: 30 | S17: 30000 | T17: 100 | U17: 100000
C20: =C7+C12+C17 -> 120000 | E20: =E7+E12+E17 -> 360000 | G20: =G7+G12+G17 -> 360000 | I20: =I7+I12+I17 -> 360000 | K20: =K7+K12+K17 -> 1200000 | M20: =M7+M12+M17 -> 120000 | O20: =O7+O12+O17 -> 360000 | Q20: =Q7+Q12+Q17 -> 360000 | S20: =S7+S12+S17 -> 360000 | U20: =U7+U12+U17 -> 1200000
